Workbook
Name Slicer_IQ_Status: #N/A
Name Slicer_JENIS_PENILAIAN: #N/A
Name Slicer_JENIS_PENILAIAN1: #N/A
Name Slicer_KATEGORI_PENILAIAN: #N/A
Name Slicer_KATEGORI_PENILAIAN2: #N/A
Name Slicer_KATEGORI_PENILAIAN3: #N/A
Name Slicer_KATEGORI_PENILAIAN4: #N/A
Name Slicer_KELAS: #N/A
Name Slicer_KELAS1: #N/A
Name Slicer_KELAS10: #N/A
Name Slicer_KELAS11: #N/A
Name Slicer_KELAS12: #N/A
Name Slicer_KELAS13: #N/A
Name Slicer_KELAS14: #N/A
Name Slicer_KELAS15: #N/A
Name Slicer_KELAS2: #N/A
Name Slicer_KELAS3: #N/A
Name Slicer_KELAS4: #N/A
Name Slicer_KELAS5: #N/A
Name Slicer_KELAS6: #N/A
Name Slicer_KELAS7: #N/A
Name Slicer_KELAS8: #N/A
Name Slicer_KELAS9: #N/A
Name Slicer_KETERANGAN_MATERI: #N/A
Name Slicer_Mapel_TDU: #N/A
Name Slicer_Mapel_TDU1: #N/A
Name Slicer_Mapel_TDU2: #N/A
Name Slicer_Mapel_TDU3: #N/A
Name Slicer_Mapel_TDU4: #N/A
Name Slicer_Mapel_TDU5: #N/A
Name Slicer_Mapel_TDU6: #N/A
Name Slicer_Mapel_TDU7: #N/A
Name Slicer_Mapel_TDU8: #N/A
Name Slicer_Mapel_TDU9: #N/A
Name Slicer_Month: #N/A
Name Slicer_Month1: #N/A
Name Slicer_Month10: #N/A
Name Slicer_Month11: #N/A
Name Slicer_Month12: #N/A
Name Slicer_Month13: #N/A
Name Slicer_Month14: #N/A
Name Slicer_Month15: #N/A
Name Slicer_Month16: #N/A
Name Slicer_Month17: #N/A
Name Slicer_Month18: #N/A
Name Slicer_Month19: #N/A
Name Slicer_Month2: #N/A
Name Slicer_Month20: #N/A
Name Slicer_Month21: #N/A
Name Slicer_Month22: #N/A
Name Slicer_Month23: #N/A
Name Slicer_Month3: #N/A
Name Slicer_Month6: #N/A
Name Slicer_Month7: #N/A
Name Slicer_Month9: #N/A
Name Slicer_NAMA: #N/A
Name Slicer_NAMA1: #N/A
Name Slicer_NAMA2: #N/A
Name Slicer_NAMA3: #N/A
Name Slicer_NAMA4: #N/A

Sheet HPL
AE1: Count of Predikat | AH1: Predikat
AE2: KELAS | AF2: Mapel TDU | AG2: Month | AH2: Sangat baik | AI2: Baik | AJ2: Cukup | AK2: Kurang
A3: Row Labels | B3: Count of Predikat | AE3: 12A | AF3: B.Indo | AG3: Jan | AH3: 0.055555556 | AI3: 0.55555556 | AJ3: 0.38888889 | AK3: 0
A4: Sangat baik | B4: 0.054521277 | AG4: Feb | AH4: 0 | AI4: 1 | AJ4: 0 | AK4: 0
A5: Baik | B5: 0.21985816 | AF5: Biologi | AG5: Jan | AH5: 0.11111111 | AI5: 0.33333333 | AJ5: 0.33333333 | AK5: 0.22222222
A6: Cukup | B6: 0.52393617 | AF6: TIK | AG6: Jan | AH6: 0 | AI6: 0.14285714 | AJ6: 0.31746032 | AK6: 0.53968254
A7: Kurang | B7: 0.2016844 | AG7: Feb | AH7: 0 | AI7: 0.25925926 | AJ7: 0.074074074 | AK7: 0.66666667
A8: Grand Total | B8: 1 | AF8: Kimia | AG8: Jan | AH8: 0.037037037 | AI8: 0.25925926 | AJ8: 0.48148148 | AK8: 0.22222222
AG9: Feb | AH9: 0 | AI9: 0 | AJ9: 0.11111111 | AK9: 0.88888889
AF10: Math | AG10: Jan | AH10: 0.41860465 | AI10: 0.11627907 | AJ10: 0.046511628 | AK10: 0.41860465
AG11: Feb | AH11: 0.5 | AI11: 0.14285714 | AJ11: 0.095238095 | AK11: 0.26190476
AF12: Kopi | AG12: Jan | AH12: 0 | AI12: 1 | AJ12: 0 | AK12: 0
AF13: B.Ing | AG13: Jan | AH13: 0 | AI13: 0.12962963 | AJ13: 0.46296296 | AK13: 0.40740741
AG14: Feb | AH14: 0 | AI14: 0.16666667 | AJ14: 0.41666667 | AK14: 0.41666667
AF15: Pancasila | AG15: Jan | AH15: 0 | AI15: 0.14285714 | AJ15: 0.75324675 | AK15: 0.1038961
AG16: Feb | AH16: 0 | AI16: 0.22222222 | AJ16: 0.73015873 | AK16: 0.047619048
AF17: Sejarah | AG17: Jan | AH17: 0.0074074074 | AI17: 0.11111111 | AJ17: 0.76296296 | AK17: 0.11851852
A18: KELAS | B18: 11A | AG18: Feb | AH18: 0.02020202 | AI18: 0.21212121 | AJ18: 0.65656566 | AK18: 0.11111111
AF19: PKWU | AG19: Jan | AH19: 0 | AI19: 1 | AJ19: 0 | AK19: 0
A20: Row Labels | B20: Count of Predikat | AF20: Fisika | AG20: Feb | AH20: 0 | AI20: 0.11111111 | AJ20: 0.44444444 | AK20: 0.44444444
A21: Sangat baik | B21: 0.054035088 | AF21: A.Katolik | AG21: Jan | AH21: 0 | AI21: 1 | AJ21: 0 | AK21: 0
A22: Baik | B22: 0.19438596 | AG22: Feb | AH22: 0 | AI22: 1 | AJ22: 0 | AK22: 0
A23: Cukup | B23: 0.55578947 | AF23: A.Kristen | AG23: Jan | AH23: 0.041666667 | AI23: 0.25 | AJ23: 0.70833333 | AK23: 0
A24: Kurang | B24: 0.19578947 | AG24: Feb | AH24: 0 | AI24: 0.375 | AJ24: 0.625 | AK24: 0
A25: Grand Total | B25: 1
A36: KELAS | B36: 11A
A38: Row Labels | B38: Count of Predikat
A39: Sangat baik | B39: 0.054035088
A40: Baik | B40: 0.19438596
A41: Cukup | B41: 0.55578947
A42: Kurang | B42: 0.19578947
A43: Grand Total | B43: 1
A55: KELAS | B55: 12A
A57: Row Labels | B57: Count of Predikat
A58: Sangat baik | B58: 0.055354994
A59: Baik | B59: 0.26353791
A60: Cukup | B60: 0.46931408
A61: Kurang | B61: 0.21179302
A62: Grand Total | B62: 1

Sheet progmat
A1: Average of MatKls
A2: KELAS | B2: Mapel TDU | C2: Month | D2: KETERANGAN MATERI | E2: Total
AA38: Average of MatKls
AA39: KELAS | AB39: NAMA | AC39: Mapel TDU | AD39: KETERANGAN MATERI | AE39: Month | AF39: Total

Sheet rerata nilai
A1: KATEGORI PENILAIAN | B1: (All) | AD1: Values
Z2: KELAS | AA2: Mapel TDU | AB2: Month | AC2: KATEGORI PENILAIAN | AD2: Average of Nilai2 | AE2: Average of KKM
D3: Values | Z3: 11A | AA3: B.Indo | AB3: Jan | AC3: Minat | AD3: 69.090909 | AE3: 65
A4: KELAS | B4: Mapel TDU | C4: Month | D4: Average of Nilai2 | E4: Average of KKM | AC4: Karakter | AD4: 69.772727 | AE4: 65
A5: 11A | B5: B.Indo | C5: Jan | D5: 65.518717 | E5: 65 | AC5: Teori | AD5: 60.254545 | AE5: 65
C6: Feb | D6: 69.572727 | E6: 65 | AC6: Nalar | AD6: 64.272727 | AE6: 65
B7: Biologi | C7: Jan | D7: 80.666667 | E7: 65 | AB7: Feb | AC7: Minat | AD7: 71.272727 | AE7: 65
B8: TIK | C8: Jan | D8: 64.315068 | E8: 65 | AC8: Karakter | AD8: 71.136364 | AE8: 65
C9: Feb | D9: 63.212121 | E9: 65 | AC9: Teori | AD9: 67.848485 | AE9: 65
B10: Kimia | C10: Jan | D10: 71.458333 | E10: 65 | AC10: Nalar | AD10: 69.121212 | AE10: 65
C11: Feb | D11: 73.125 | E11: 65 | AA11: Biologi | AB11: Jan | AC11: Teori | AD11: 80.666667 | AE11: 65
B12: Math | C12: Jan | D12: 65.191011 | E12: 65 | AA12: TIK | AB12: Jan | AC12: Minat | AD12: 70 | AE12: 65
C13: Feb | D13: 70.709091 | E13: 65 | AC13: Karakter | AD13: 73.181818 | AE13: 65
B14: Kopi | C14: Jan | D14: 70.75 | E14: 65 | AC14: Teori | AD14: 61.25 | AE14: 65
C15: Feb | D15: 78 | E15: 65 | AC15: Nalar | AD15: 60.909091 | AE15: 65
B16: B.Ing | C16: Jan | D16: 50.372093 | E16: 65 | AC16: Skill | AD16: 61.25 | AE16: 65
C17: Feb | D17: 60.685185 | E17: 65 | AB17: Feb | AC17: Karakter | AD17: 74.545455 | AE17: 65
B18: Pancasila | C18: Jan | D18: 73.902174 | E18: 65 | AC18: Teori | AD18: 56.727273 | AE18: 65
C19: Feb | D19: 73.288462 | E19: 65 | AC19: Skill | AD19: 58.363636 | AE19: 65
B20: Sejarah | C20: Jan | D20: 72.424242 | E20: 65 | AA20: Kimia | AB20: Jan | AC20: Nalar | AD20: 66.25 | AE20: 65
C21: Feb | D21: 69.126126 | E21: 65 | AC21: Skill | AD21: 76.666667 | AE21: 65
B22: PKWU | C22: Jan | D22: 80.8 | E22: 65 | AB22: Feb | AC22: Teori | AD22: 73.125 | AE22: 65
C23: Feb | D23: 78.561404 | E23: 65 | AA23: Math | AB23: Jan | AC23: Karakter | AD23: 78.75 | AE23: 65
B24: Fisika | C24: Feb | D24: 70.904762 | E24: 65 | AC24: Teori | AD24: 61.26087 | AE24: 65
B25: Tepung | C25: Jan | D25: 87.5 | E25: 65 | AB25: Feb | AC25: Teori | AD25: 70.709091 | AE25: 65
C26: Feb | D26: 78.615385 | E26: 65 | AA26: Kopi | AB26: Jan | AC26: Skill | AD26: 70.75 | AE26: 65
AB27: Feb | AC27: Skill | AD27: 78 | AE27: 65
AA28: B.Ing | AB28: Jan | AC28: Karakter | AD28: 70.833333 | AE28: 65
AC29: Teori | AD29: 47.8 | AE29: 65
AC30: Nalar | AD30: 24.8 | AE30: 65
AC31: Skill | AD31: 43.181818 | AE31: 65
AB32: Feb | AC32: Teori | AD32: 59.28125 | AE32: 65
AC33: Skill | AD33: 62.727273 | AE33: 65
AA34: Pancasila | AB34: Jan | AC34: Minat | AD34: 71.826087 | AE34: 65
AC35: Karakter | AD35: 76.130435 | AE35: 65
AC36: Teori | AD36: 74.73913 | AE36: 65
AC37: Nalar | AD37: 72.913043 | AE37: 65
AB38: Feb | AC38: Minat | AD38: 75.75 | AE38: 65
AC39: Karakter | AD39: 75.75 | AE39: 65
AC40: Teori | AD40: 73.066667 | AE40: 65
...

Sheet rerata siswa
A1: KATEGORI PENILAIAN | B1: (All) | AI1: Values
AC2: KELAS | AD2: NAMA | AE2: Mapel TDU | AF2: KATEGORI PENILAIAN | AG2: JENIS PENILAIAN | AH2: Month | AI2: Average of Nilai2 | AJ2: Average of KKM
E3: Values | AC3: 11A | AD3: Agustinus Tipagau | AE3: B.Indo | AF3: Minat | AG3: Fokus, aktif berpartisipasi dan bertanya atau menanggapi | AH3: Jan | AI3: 68.5 | AJ3: 65
A4: KELAS | B4: NAMA | C4: Mapel TDU | D4: Month | E4: Average of Nilai2 | F4: Average of KKM | AH4: Feb | AI4: 70 | AJ4: 65
A5: 11A | B5: Agustinus Tipagau | C5: Math | D5: Jan | E5: 68 | F5: 65 | AF5: Karakter | AG5: Mandiri | AH5: Jan | AI5: 70 | AJ5: 65
D6: Feb | E6: 81.4 | F6: 65 | AH6: Feb | AI6: 67.5 | AJ6: 65
B7: Apia Miagoni | C7: Math | D7: Jan | E7: 69 | F7: 65 | AF7: Teori | AG7: Kognitif Formatif | AH7: Jan | AI7: 68.75 | AJ7: 65
D8: Feb | E8: 73.2 | F8: 65 | AH8: Feb | AI8: 66.333333 | AJ8: 65
B9: Etty Ebrata Holombau | C9: Math | D9: Jan | E9: 67.222222 | F9: 65 | AG9: Kognitif Sumatif | AH9: Jan | AI9: 10 | AJ9: 65
D10: Feb | E10: 82.6 | F10: 65 | AF10: Nalar | AG10: Evaluasi | AH10: Jan | AI10: 65 | AJ10: 65
B11: Jonias Bagau | C11: Math | D11: Jan | E11: 55 | F11: 65 | AH11: Feb | AI11: 65.666667 | AJ11: 65
D12: Feb | E12: 73.6 | F12: 65 | AG12: Analisa | AH12: Jan | AI12: 68 | AJ12: 65
B13: Jupiten Bagau | C13: Math | D13: Jan | E13: 47.857143 | F13: 65 | AE13: Biologi | AF13: Teori | AG13: Kognitif Formatif | AH13: Jan | AI13: 40 | AJ13: 65
D14: Feb | E14: 63.6 | F14: 65 | AE14: TIK | AF14: Minat | AG14: Fokus, aktif berpartisipasi dan bertanya atau menanggapi | AH14: Jan | AI14: 65 | AJ14: 65
B15: Lince Tigi | C15: Math | D15: Jan | E15: 83.888889 | F15: 65 | AF15: Karakter | AG15: Beriman, bertakwa kepada Tuhan YME dan berakhlak mulia | AH15: Jan | AI15: 70 | AJ15: 65
D16: Feb | E16: 89.6 | F16: 65 | AH16: Feb | AI16: 75 | AJ16: 65
B17: Lovin Miagoni | C17: Math | D17: Jan | E17: 58.75 | F17: 65 | AF17: Teori | AG17: Praktik Formatif | AH17: Jan | AI17: 60 | AJ17: 65
D18: Feb | E18: 30 | F18: 65 | AH18: Feb | AI18: 50 | AJ18: 65
B19: Onance Mbaguau | C19: Math | D19: Jan | E19: 70 | F19: 65 | AF19: Nalar | AG19: Kreasi | AH19: Jan | AI19: 60 | AJ19: 65
D20: Feb | E20: 65 | F20: 65 | AF20: Skill | AG20: Konsep | AH20: Jan | AI20: 60 | AJ20: 65
B21: Roison Sondegau | C21: Math | D21: Jan | E21: 70 | F21: 65 | AH21: Feb | AI21: 55 | AJ21: 65
D22: Feb | E22: 76.8 | F22: 65 | AE22: Kimia | AF22: Teori | AG22: Kognitif Formatif | AH22: Feb | AI22: 66 | AJ22: 65
B23: Wenes Tapani | C23: Math | D23: Jan | E23: 65.111111 | F23: 65 | AF23: Nalar | AG23: Analisa | AH23: Jan | AI23: 70 | AJ23: 65
D24: Feb | E24: 66.2 | F24: 65 | AF24: Skill | AG24: Discovery | AH24: Jan | AI24: 65 | AJ24: 65
B25: Yoas Bagau | C25: Math | D25: Jan | E25: 51.428571 | F25: 65 | AE25: Math | AF25: Karakter | AG25: Beriman, bertakwa kepada Tuhan YME dan berakhlak mulia | AH25: Jan | AI25: 90 | AJ25: 65
D26: Feb | E26: 75.8 | F26: 65 | AF26: Teori | AG26: Kognitif Formatif | AH26: Jan | AI26: 62.5 | AJ26: 65
B27: Yohanes Bagau | C27: Math | D27: Jan | E27: 70 | F27: 65 | AH27: Feb | AI27: 81.4 | AJ27: 65
AE28: Kopi | AF28: Skill | AG28: Konsep | AH28: Jan | AI28: 65 | AJ28: 65
AH29: Feb | AI29: 80 | AJ29: 65
AG30: Rencana Sukses | AH30: Jan | AI30: 80 | AJ30: 65
AE31: B.Ing | AF31: Karakter | AG31: Mandiri | AH31: Jan | AI31: 30 | AJ31: 65
AG32: Beriman, bertakwa kepada Tuhan YME dan berakhlak mulia | AH32: Jan | AI32: 25 | AJ32: 65
AF33: Teori | AG33: Kognitif Formatif | AH33: Jan | AI33: 10 | AJ33: 65
AH34: Feb | AI34: 60 | AJ34: 65
AF35: Skill | AG35: Konsep | AH35: Jan | AI35: 10 | AJ35: 65
AG36: Discovery | AH36: Feb | AI36: 67.5 | AJ36: 65
AD37: Apia Miagoni | AE37: B.Indo | AF37: Minat | AG37: Fokus, aktif berpartisipasi dan bertanya atau menanggapi | AH37: Jan | AI37: 68.75 | AJ37: 65
AH38: Feb | AI38: 72.5 | AJ38: 65
AF39: Karakter | AG39: Mandiri | AH39: Jan | AI39: 70 | AJ39: 65
AH40: Feb | AI40: 75 | AJ40: 65
...

Sheet skill
AY1: Average of Nilai2 | BD1: KATEGORI PENILAIAN
AY2: PROYEK | AZ2: SKILL | BA2: Month | BB2: Wk# | BC2: SUB SKILL | BD2: Skill | BE2: Teori | BF2: Nalar | BG2: Karakter | BH2: Minat
A3: Average of Nilai2 | E3: KATEGORI PENILAIAN | AY3: Pengolahan Kopi atau Tepung | AZ3: Product development | BA3: Jan | BB3: Wk.2 | BC3: Pengembangan produk inovasi | BD3: 67.583333 | BE3: 58.5 | BG3: 71.25
A4: PROYEK | B4: Month | C4: Wk# | D4: SKILL | E4: Skill | F4: Teori | G4: Nalar | H4: Karakter | I4: Minat | BC4: Produksi berkelanjutan | BD4: 67.5
A5: Pengolahan Kopi atau Tepung | B5: Jan | C5: Wk.2 | D5: Product development | E5: 67.555556 | F5: 58.5 | H5: 71.25 | BB5: Wk.3 | BC5: Pengembangan produk inovasi | BD5: 90 | BE5: 61.14 | BF5: 63.272727 | BG5: 69.545455 | BH5: 69.090909
D6: Inovasi market | G6: 71.111111 | BC6: Produksi berkelanjutan | BE6: 70.619048 | BF6: 69.695652 | BG6: 79.652174 | BH6: 70.826087
C7: Wk.3 | D7: Product development | E7: 90 | F7: 65.467391 | G7: 66.555556 | H7: 76.382353 | I7: 70.264706 | BB7: Wk.4 | BC7: Pengembangan produk inovasi | BD7: 55.333333 | BE7: 64.522727 | BF7: 47.409091 | BG7: 82.647059 | BH7: 70
D8: Inovasi market | E8: 65.740741 | F8: 69.544118 | G8: 67.333333 | H8: 75.259259 | I8: 74.5 | BC8: Produksi berkelanjutan | BE8: 61.415094 | BF8: 66 | BG8: 76.666667 | BH8: 69.318182
C9: Wk.4 | D9: Product development | E9: 55.333333 | F9: 62.824742 | G9: 56.704545 | H9: 78.389831 | I9: 69.545455 | BB9: Wk.5 | BC9: Pengembangan produk inovasi | BD9: 73.875 | BE9: 59.941176 | BG9: 70.416667
D10: Inovasi market | E10: 84 | F10: 75.393443 | G10: 67.407407 | H10: 77.333333 | I10: 72.666667 | BC10: Produksi berkelanjutan | BE10: 68.769231 | BF10: 68.068182 | BG10: 72.659091 | BH10: 69.727273
C11: Wk.5 | D11: Product development | E11: 73.875 | F11: 66.594203 | G11: 68.068182 | H11: 72.178571 | I11: 69.727273 | BA11: Feb | BB11: Wk.6 | BC11: Pengembangan produk inovasi | BD11: 78 | BE11: 76.521739
D12: Inovasi market | E12: 71.111111 | F12: 74.055556 | G12: 76.081081 | H12: 75.535714 | I12: 69.777778 | BC12: Produksi berkelanjutan | BD12: 69.956522 | BE12: 74.955056 | BF12: 74.264706 | BG12: 71.257143 | BH12: 70.411765
B13: Feb | C13: Wk.6 | D13: Product development | E13: 74.06383 | F13: 75.276786 | G13: 74.264706 | H13: 71.257143 | I13: 70.411765 | BB13: Wk.7 | BC13: Pengembangan produk inovasi | BD13: 66.659091 | BE13: 61.946429 | BF13: 78 | BG13: 74.545455
D14: Inovasi market | E14: 75.333333 | F14: 75.907407 | G14: 72.5 | H14: 76.027778 | I14: 70.222222 | BC14: Produksi berkelanjutan | BE14: 66.378788 | BF14: 65.636364 | BG14: 71.909091 | BH14: 69
C15: Wk.7 | D15: Product development | E15: 66.659091 | F15: 64.344262 | G15: 70 | H15: 73.227273 | I15: 69 | BB15: Wk.8 | BC15: Pengembangan produk inovasi | BD15: 76.73913 | BE15: 75.782609
D16: Inovasi market | E16: 62.777778 | F16: 68.583333 | G16: 70.444444 | H16: 78.888889 | I16: 76.055556 | BC16: Produksi berkelanjutan | BE16: 68 | BF16: 66.636364 | BG16: 72.045455 | BH16: 72.545455
C17: Wk.8 | D17: Product development | E17: 76.73913 | F17: 71.977778 | G17: 66.636364 | H17: 72.045455 | I17: 72.545455 | BB17: Wk.9 | BC17: Pengembangan produk inovasi | BD17: 80 | BE17: 80
D18: Inovasi market | F18: 70 | G18: 71.111111 | H18: 85 | I18: 70 | BC18: Produksi berkelanjutan | BE18: 64.6
C19: Wk.9 | D19: Product development | E19: 80 | F19: 72.3
D20: Inovasi market | F20: 90.333333 | G20: 82.222222

Sheet stnk
A1: KELAS | B1: 11A | AU1: PROYEK | AV1: Pengolahan Kopi atau Tepung
A3: Average of Nilai | C3: Mapel TDU | AU3: Average of Nilai2 | AX3: KATEGORI PENILAIAN
A4: Month | B4: Wk# | C4: Skill | D4: Teori | E4: Nalar | F4: Karakter | G4: Minat | H4: B.Indo | I4: Math | AU4: KELAS | AV4: Month | AW4: Wk# | AX4: Skill | AY4: Teori | AZ4: Nalar | BA4: Karakter | BB4: Minat
A5: Jan | B5: Wk.2 | C5: 67.555556 | D5: 58.5 | F5: 71.25 | AU5: 11A | AV5: Jan | AW5: Wk.3 | AX5: 90 | AY5: 65.467391 | AZ5: 66.555556 | BA5: 76.382353 | BB5: 70.264706
A6: Jan | B6: Wk.3 | C6: 90 | D6: 64.493827 | E6: 66.555556 | F6: 76.382353 | G6: 70.264706 | H6: 48.090909 | I6: 69.052632 | AW6: Wk.4 | AX6: 55.333333 | AY6: 62.824742 | AZ6: 56.704545 | BA6: 78.389831 | BB6: 69.545455
A7: Jan | B7: Wk.4 | C7: 55.333333 | D7: 61.174419 | E7: 56.704545 | F7: 78.389831 | G7: 69.545455 | H7: 71.818182 | I7: 59.404762 | AW7: Wk.5 | AX7: 73.875 | AY7: 66.594203 | AZ7: 68.068182 | BA7: 72.178571 | BB7: 69.727273
A8: Jan | B8: Wk.5 | C8: 71.190476 | D8: 66.594203 | E8: 68.068182 | F8: 72.178571 | G8: 69.727273 | H8: 66.636364 | I8: 52.5 | AW8: Wk.2 | AX8: 67.555556 | AY8: 58.5 | BA8: 71.25
A9: Feb | B9: Wk.6 | C9: 74.06383 | D9: 75.316832 | E9: 74.264706 | F9: 71.257143 | G9: 70.411765 | H9: 68.363636 | I9: 79.969697 | AV9: Feb | AW9: Wk.6 | AX9: 74.06383 | AY9: 75.276786 | AZ9: 74.264706 | BA9: 71.257143 | BB9: 70.411765
A10: Feb | B10: Wk.7 | C10: 66.659091 | D10: 64.344262 | E10: 70 | F10: 73.227273 | G10: 69 | H10: 66.636364 | I10: 56.818182 | AW10: Wk.7 | AX10: 66.659091 | AY10: 64.344262 | AZ10: 70 | BA10: 73.227273 | BB10: 69
A11: Feb | B11: Wk.8 | C11: 76.73913 | D11: 71.977778 | E11: 66.636364 | F11: 72.045455 | G11: 72.545455 | H11: 68.545455 | AW11: Wk.8 | AX11: 76.73913 | AY11: 71.977778 | AZ11: 66.636364 | BA11: 72.045455 | BB11: 72.545455
A12: Feb | B12: Wk.9 | C12: 80 | D12: 72.3 | AW12: Wk.9 | AX12: 80 | AY12: 72.3
AU13: 12A | AV13: Jan | AW13: Wk.3 | AX13: 65.740741 | AY13: 69.544118 | AZ13: 67.333333 | BA13: 75.259259 | BB13: 74.5
AW14: Wk.4 | AX14: 84 | AY14: 75.393443 | AZ14: 67.407407 | BA14: 77.333333 | BB14: 72.666667
AW15: Wk.5 | AX15: 71.111111 | AY15: 74.055556 | AZ15: 76.081081 | BA15: 75.535714 | BB15: 69.777778
AW16: Wk.2 | AZ16: 71.111111
AV17: Feb | AW17: Wk.6 | AX17: 75.333333 | AY17: 75.907407 | AZ17: 72.5 | BA17: 76.027778 | BB17: 70.222222
AW18: Wk.7 | AX18: 62.777778 | AY18: 68.583333 | AZ18: 70.444444 | BA18: 78.888889 | BB18: 76.055556
AW19: Wk.8 | AY19: 70 | AZ19: 71.111111 | BA19: 85 | BB19: 70
AW20: Wk.9 | AY20: 90.333333 | AZ20: 82.222222
AE66: Average of Nilai2 | AK66: KATEGORI PENILAIAN
AE67: KELAS | AF67: NAMA | AG67: PROYEK | AH67: SKILL | AI67: Month | AJ67: Wk# | AK67: Skill | AL67: Teori | AM67: Nalar | AN67: Karakter | AO67: Minat
AE68: 11A | AF68: Agustinus Tipagau | AG68: Pengolahan Kopi atau Tepung | AH68: Product development | AI68: Jan | AJ68: Wk.3 | AL68: 61.375 | AM68: 64.5 | AN68: 71.666667 | AO68: 70
AJ69: Wk.4 | AK69: 73.333333 | AL69: 59.666667 | AM69: 66.666667 | AN69: 77.5 | AO69: 68.333333
AJ70: Wk.5 | AK70: 70 | AL70: 65 | AM70: 65 | AN70: 58.75 | AO70: 66.333333
AJ71: Wk.2 | AK71: 51.25 | AL71: 10 | AN71: 30
AI72: Feb | AJ72: Wk.6 | AK72: 67.5 | AL72: 78.555556 | AM72: 66.666667 | AN72: 68.333333 | AO72: 68.333333
AJ73: Wk.7 | AK73: 68.75 | AL73: 62.5 | AM73: 63.5 | AN73: 72 | AO73: 69
AJ74: Wk.8 | AK74: 75 | AL74: 68.25 | AM74: 65 | AN74: 70 | AO74: 70
AJ75: Wk.9 | AL75: 61
K81: Mapel TDU | L81: (Multiple Items)
K83: Average of Nilai2 | N83: KATEGORI PENILAIAN
K84: KELAS | L84: Month | M84: Wk#

Sheet karakter
A1: Mapel TDU | B1: (Multiple Items)
AT2: KELAS | AU2: (All)
A3: Row Labels | B3: Count of Predikat Krktr | AT3: KATEGORI PENILAIAN | AU3: (Multiple Items)
A4: Sangat baik | B4: 0.098701299
A5: Baik | B5: 0.30649351 | AT5: Count of Predikat Krktr | AW5: Predikat Krktr
A6: Cukup | B6: 0.46493506 | AT6: JENIS PENILAIAN | AU6: Mapel TDU | AV6: Month | AW6: Sangat baik | AX6: Baik | AY6: Cukup | AZ6: Kurang | BA6: Sangat kurang
A7: Kurang | B7: 0.1012987 | AT7: Mandiri | AU7: B.Indo | AV7: Jan | AW7: 0 | AX7: 0 | AY7: 0.86363636 | AZ7: 0.13636364 | BA7: 0
A8: Sangat kurang | B8: 0.028571429 | AV8: Feb | AW8: 0 | AX8: 0.55 | AY8: 0.35 | AZ8: 0.1 | BA8: 0
A9: Grand Total | B9: 1 | AU9: TIK | AV9: Jan | AW9: 0 | AX9: 0.77777778 | AY9: 0.22222222 | AZ9: 0 | BA9: 0
AV10: Feb | AW10: 0 | AX10: 0.77777778 | AY10: 0.22222222 | AZ10: 0 | BA10: 0
AU11: B.Ing | AV11: Jan | AW11: 0.52380952 | AX11: 0 | AY11: 0 | AZ11: 0.38095238 | BA11: 0.095238095
AV12: Feb | AW12: 0.11111111 | AX12: 0.33333333 | AY12: 0.11111111 | AZ12: 0 | BA12: 0.44444444
AU13: Pancasila | AV13: Jan | AW13: 0 | AX13: 0.13333333 | AY13: 0.86666667 | AZ13: 0 | BA13: 0
AU14: Sejarah | AV14: Jan | AW14: 0.043478261 | AX14: 0.44927536 | AY14: 0.50724638 | AZ14: 0 | BA14: 0
AV15: Feb | AW15: 0 | AX15: 0.30769231 | AY15: 0.59615385 | AZ15: 0.096153846 | BA15: 0
AT16: Bergotong royong | AU16: Kopi | AV16: Jan | AW16: 0 | AX16: 1 | AY16: 0 | AZ16: 0 | BA16: 0
AU17: PKWU | AV17: Jan | AW17: 0.375 | AX17: 0.625 | AY17: 0 | AZ17: 0 | BA17: 0
AU18: Tepung | AV18: Jan | AW18: 1 | AX18: 0 | AY18: 0 | AZ18: 0 | BA18: 0
AT19: Beriman, bertakwa kepada Tuhan YME dan berakhlak mulia | AU19: TIK | AV19: Jan | AW19: 0 | AX19: 0.45454545 | AY19: 0.27272727 | AZ19: 0.27272727 | BA19: 0
AV20: Feb | AW20: 0 | AX20: 0.45454545 | AY20: 0.27272727 | AZ20: 0.27272727 | BA20: 0
AU21: Math | AV21: Jan | AW21: 0.55 | AX21: 0 | AY21: 0 | AZ21: 0.45 | BA21: 0
AU22: B.Ing | AV22: Jan | AW22: 0.5 | AX22: 0 | AY22: 0.083333333 | AZ22: 0 | BA22: 0.41666667
AU23: Pancasila | AV23: Jan | AW23: 0 | AX23: 0 | AY23: 1 | AZ23: 0 | BA23: 0
AV24: Feb | AW24: 0 | AX24: 0.38095238 | AY24: 0.57142857 | AZ24: 0.047619048 | BA24: 0
A32: Mapel TDU | B32: (Multiple Items)
A34: Count of Predikat Krktr | C34: Predikat Krktr
A35: KELAS | B35: Month | C35: Sangat baik | D35: Baik | E35: Cukup | F35: Kurang | G35: Sangat kurang
A36: 11A | B36: Jan | C36: 0.19875776 | D36: 0.19254658 | E36: 0.42857143 | F36: 0.13664596 | G36: 0.043478261
B37: Feb | C37: 0 | D37: 0.15189873 | E37: 0.6835443 | F37: 0.16455696 | G37: 0
A38: 12A | B38: Jan | C38: 0.06097561 | D38: 0.31707317 | E38: 0.57317073 | F38: 0.048780488 | G38: 0
B39: Feb | C39: 0.015873016 | D39: 0.77777778 | E39: 0.14285714 | F39: 0 | G39: 0.063492063
AJ69: KATEGORI PENILAIAN | AK69: (Multiple Items)
A70: Count of Predikat Krktr | B70: Column Labels | AJ70: Mapel TDU | AK70: (Multiple Items)
A71: Row Labels | B71: Sangat baik | C71: Baik | D71: Cukup | E71: Kurang | F71: Sangat kurang
A72: Pengolahan Kopi atau Tepung | AJ72: Average of Nilai2 | AN72: Predikat Krktr
A73: 11A | AJ73: NAMA | AK73: JENIS PENILAIAN | AL73: BENTUK PENILAIAN | AM73: Month | AN73: Sangat baik | AO73: Baik | AP73: Cukup
A74: B.Indo | AJ74: Apia Miagoni | AK74: Mandiri | AL74: Pantang menyerah dalam belajar dan mengerjakan tugas | AM74: Jan | AP74: 70
A75: Jan | B75: 0 | C75: 0 | D75: 0.86363636 | E75: 0.13636364 | F75: 0 | AM75: Feb | AP75: 70
A76: Feb | B76: 0 | C76: 0.18181818 | D76: 0.63636364 | E76: 0.18181818 | F76: 0 | AL76: Keinginan untuk memperkaya pengetahuan melalui literasi | AM76: Jan | AN76: 90
A77: TIK | AL77: Mengerjakan setiap tugas dan kewajiban di sekolah | AM77: Jan | AP77: 70
...

Sheet guru
A3: Count of JENIS PENILAIAN | D3: KATEGORI PENILAIAN | O3: Count of NAMA | R3: Wk#
A4: KELAS | B4: Mapel TDU | C4: Wk# | D4: Skill | E4: Teori | F4: Nalar | G4: Karakter | H4: Minat | O4: KELAS | P4: NAMA GURU | Q4: Mapel TDU | S4: Wk.2 | T4: Wk.3 | U4: Wk.4 | V4: Wk.5 | W4: Wk.6 | X4: Wk.7 | Y4: Wk.8 | Z4: Wk.9
A5: 11A | B5: B.Indo | C5: Wk.3 | E5: 22 | F5: 11 | G5: 11 | H5: 11 | O5: 11A | P5: Bonafasia Jaju, S. Pd., Gr. | R5: 48
A6: 11A | B6: B.Indo | C6: Wk.4 | E6: 11 | F6: 11 | G6: 11 | H6: 11 | O6: 11A | P6: Bonafasia Jaju, S. Pd., Gr. | Q6: B.Indo | T6: 55 | U6: 44 | V6: 88 | W6: 44 | X6: 22 | Y6: 44
A7: 11A | B7: B.Indo | C7: Wk.5 | E7: 22 | F7: 22 | G7: 22 | H7: 22 | O7: 11A | P7: Bonafasia Jaju, S. Pd., Gr. | Q7: Sejarah | T7: 44 | U7: 44 | V7: 44 | W7: 45 | X7: 44 | Y7: 22
A8: 11A | B8: B.Indo | C8: Wk.6 | E8: 11 | F8: 11 | G8: 11 | H8: 11 | O8: 11A | P8: Bonafasia Jaju, S. Pd., Gr. | Q8: A.Kristen | T8: 8 | U8: 8 | V8: 8 | W8: 8
A9: 11A | B9: B.Indo | C9: Wk.7 | E9: 11 | F9: 11 | O9: 11A | P9: Eka Dewi Sriyani, S.Pd., M.Si., Gr. | Q9: Biologi | U9: 12
A10: 11A | B10: B.Indo | C10: Wk.8 | E10: 11 | F10: 11 | G10: 11 | H10: 11 | O10: 11A | P10: Febriyani Sulistyaningsih, M.Pd., Gr. | R10: 19
A11: 11A | B11: Biologi | C11: Wk.4 | E11: 12 | O11: 11A | P11: Febriyani Sulistyaningsih, M.Pd., Gr. | Q11: Kimia | S11: 12 | U11: 12 | X11: 12 | Y11: 12
A12: 11A | B12: TIK | C12: Wk.3 | E12: 11 | F12: 11 | O12: 11A | P12: Febriyani Sulistyaningsih, M.Pd., Gr. | Q12: Kopi | S12: 6 | U12: 6 | X12: 5
A13: 11A | B13: TIK | C13: Wk.4 | D13: 11 | G13: 11 | H13: 11 | O13: 11A | P13: Febriyani Sulistyaningsih, M.Pd., Gr. | Q13: PKWU | S13: 6 | U13: 6 | X13: 5
A14: 11A | B14: TIK | C14: Wk.5 | D14: 9 | E14: 9 | O14: 11A | P14: Fenty Yunia Vianarika, S.Pd., Gr. | R14: 129
A15: 11A | B15: TIK | C15: Wk.7 | D15: 11 | E15: 11 | G15: 11 | O15: 11A | P15: Fenty Yunia Vianarika, S.Pd., Gr. | Q15: B.Ing | S15: 36 | U15: 30 | V15: 20 | X15: 32 | Y15: 22
A16: 11A | B16: Kimia | C16: Wk.2 | D16: 12 | O16: 11A | P16: Fenty Yunia Vianarika, S.Pd., Gr. | Q16: Fisika | W16: 11 | Z16: 10
A17: 11A | B17: Kimia | C17: Wk.4 | F17: 12 | O17: 11A | P17: Fenty Yunia Vianarika, S.Pd., Gr. | Q17: Pancasila | T17: 48 | V17: 44 | W17: 82 | X17: 22
A18: 11A | B18: Kimia | C18: Wk.7 | E18: 12 | O18: 11A | P18: Fenty Yunia Vianarika, S.Pd., Gr. | Q18: PKWU | T18: 9 | U18: 3 | V18: 6 | W18: 18 | X18: 18 | Y18: 6 | Z18: 10
A19: 11A | B19: Kimia | C19: Wk.8 | E19: 12 | O19: 11A | P19: Fenty Yunia Vianarika, S.Pd., Gr. | Q19: Tepung | T19: 9 | U19: 3 | V19: 6 | W19: 18 | X19: 18 | Y19: 6 | Z19: 10
A20: 11A | B20: Math | C20: Wk.3 | E20: 19 | O20: 11A | P20: Fenty Yunia Vianarika, S.Pd., Gr. | Q20: A.Katolik | T20: 3 | U20: 3 | V20: 3 | W20: 3
A21: 11A | B21: Math | C21: Wk.4 | E21: 42 | G21: 20 | O21: 11A | P21: Gabriel Iwan Prasetyono, M.Si. | R21: 24
A22: 11A | B22: Math | C22: Wk.5 | E22: 8 | O22: 11A | P22: Gabriel Iwan Prasetyono, M.Si. | Q22: Math | T22: 19 | U22: 62 | V22: 8 | W22: 33 | X22: 22
A23: 11A | B23: Math | C23: Wk.6 | E23: 33 | O23: 11A | P23: Rizal Fahmi, A.Md.Kom | R23: 14
A24: 11A | B24: Math | C24: Wk.7 | E24: 22 | O24: 11A | P24: Rizal Fahmi, A.Md.Kom | Q24: TIK | T24: 22 | U24: 33 | V24: 18 | X24: 33
A25: 11A | B25: Kopi | C25: Wk.2 | D25: 6 | O25: 12A | P25: Bonafasia Jaju, S. Pd., Gr. | Q25: Sejarah | T25: 36 | U25: 36 | V25: 63 | W25: 36 | X25: 36 | Y25: 27
A26: 11A | B26: Kopi | C26: Wk.4 | D26: 6 | O26: 12A | P26: Bonafasia Jaju, S. Pd., Gr. | Q26: A.Katolik | T26: 1 | U26: 1 | V26: 1 | W26: 1
A27: 11A | B27: Kopi | C27: Wk.7 | D27: 5 | O27: 12A | P27: Bonafasia Jaju, S. Pd., Gr. | Q27: A.Kristen | T27: 8 | U27: 8 | V27: 8 | W27: 8
A28: 11A | B28: B.Ing | C28: Wk.2 | D28: 12 | E28: 12 | G28: 12 | O28: 12A | P28: Eka Dewi Sriyani, S.Pd., M.Si., Gr. | Q28: Biologi | T28: 9
A29: 11A | B29: B.Ing | C29: Wk.4 | D29: 10 | E29: 10 | F29: 10 | O29: 12A | P29: Ermelinda Janul, S. Pd., Gr. | R29: 4
A30: 11A | B30: B.Ing | C30: Wk.5 | E30: 8 | G30: 12 | O30: 12A | P30: Ermelinda Janul, S. Pd., Gr. | Q30: Pancasila | T30: 41 | U30: 36 | W30: 63
A31: 11A | B31: B.Ing | C31: Wk.7 | D31: 11 | E31: 21 | O31: 12A | P31: Febriyani Sulistyaningsih, M.Pd., Gr. | Q31: Kimia | S31: 9 | T31: 9 | V31: 9 | X31: 9
A32: 11A | B32: B.Ing | C32: Wk.8 | D32: 11 | E32: 11 | O32: 12A | P32: Fenty Yunia Vianarika, S.Pd., Gr. | Q32: B.Ing | T32: 36 | V32: 18 | W32: 36
A33: 11A | B33: Pancasila | C33: Wk.3 | E33: 12 | F33: 12 | G33: 12 | H33: 12 | O33: 12A | P33: Fenty Yunia Vianarika, S.Pd., Gr. | Q33: Fisika | X33: 9
A34: 11A | B34: Pancasila | C34: Wk.5 | E34: 11 | F34: 11 | G34: 11 | H34: 11 | O34: 12A | P34: Fenty Yunia Vianarika, S.Pd., Gr. | Q34: TIK | T34: 18 | U34: 27 | V34: 18 | X34: 27
A35: 11A | B35: Pancasila | C35: Wk.6 | D35: 23 | E35: 23 | F35: 12 | G35: 12 | H35: 12 | O35: 12A | P35: Gabriel Iwan Prasetyono, M.Si. | R35: 5
A36: 11A | B36: Pancasila | C36: Wk.7 | E36: 22 | O36: 12A | P36: Gabriel Iwan Prasetyono, M.Si. | Q36: Math | T36: 9 | U36: 34 | W36: 9 | X36: 24 | Z36: 9
A37: 11A | B37: Sejarah | C37: Wk.3 | E37: 11 | F37: 11 | G37: 11 | H37: 11 | O37: 12A | P37: Yanto Sutrisno Saragih, S.Pd., Gr. | R37: 12
A38: 11A | B38: Sejarah | C38: Wk.4 | E38: 11 | F38: 11 | G38: 11 | H38: 11 | O38: 12A | P38: Yanto Sutrisno Saragih, S.Pd., Gr. | Q38: B.Indo | V38: 18 | W38: 9 | X38: 18 | Y38: 18 | Z38: 9
A39: 11A | B39: Sejarah | C39: Wk.5 | E39: 11 | F39: 11 | G39: 11 | H39: 11 | O39: 12A | P39: Yanto Sutrisno Saragih, S.Pd., Gr. | Q39: Kopi | U39: 5 | V39: 10
A40: 11A | B40: Sejarah | C40: Wk.6 | E40: 11 | F40: 11 | G40: 12 | H40: 11 | O40: 12A | P40: Yanto Sutrisno Saragih, S.Pd., Gr. | Q40: PKWU | U40: 5 | V40: 10
A41: 11A | B41: Sejarah | C41: Wk.7 | E41: 11 | F41: 11 | G41: 11 | H41: 11
A42: 11A | B42: Sejarah | C42: Wk.8 | E42: 11 | G42: 11
...

Sheet IQ-stnkm
A3: Average of Nilai2 | D3: KATEGORI PENILAIAN
A4: KELAS | B4: IQ Status | C4: Month | D4: Skill | E4: Teori | F4: Nalar | G4: Karakter | H4: Minat
A5: 11A | B5: Extremely low | C5: Jan | D5: 63.277778 | E5: 66.047619 | F5: 67.272727 | G5: 68.346154 | H5: 71.052632
A6: 11A | B6: Extremely low | C6: Feb | D6: 73.285714 | E6: 73.479167 | F6: 70.833333 | G6: 72.285714 | H6: 71.7
A7: 11A | B7: Low average | C7: Jan | D7: 54.333333 | E7: 49.695652 | F7: 50.363636 | G7: 76.076923 | H7: 66.222222
A8: 11A | B8: Low average | C8: Feb | D8: 53.571429 | E8: 47.083333 | F8: 58.333333 | G8: 69.571429 | H8: 69.4
A9: 11A | B9: Average | C9: Jan | D9: 71.978723 | E9: 65.445378 | F9: 63.633333 | G9: 76.111111 | H9: 68.58
A10: 11A | B10: Average | C10: Feb | D10: 72.288136 | E10: 69.489051 | F10: 69.75 | G10: 72 | H10: 70.04
A11: 11A | B11: High average | C11: Jan | D11: 75.458333 | E11: 73.148148 | F11: 66.25 | G11: 83.53125 | H11: 73
A12: 11A | B12: High average | C12: Feb | D12: 75.566667 | E12: 78.25 | F12: 77.6875 | G12: 75 | H12: 72
A13: 11A | B13: Superior | C13: Jan | D13: 62.142857 | E13: 53.636364 | F13: 65.727273 | G13: 71.230769 | H13: 69.6
A14: 11A | B14: Superior | C14: Feb | D14: 75.076923 | E14: 69.444444 | F14: 74.625 | G14: 69.428571 | H14: 70.2

Sheet Sheet2
A1: NO | B1: NIS | C1: KELAS | D1: NAMA | E1: ASAL KABUPATEN | F1: TANGGAL | G1: Day | H1: Month | I1: Year | J1: KATEGORI PENILAIAN | K1: JENIS PENILAIAN | L1: BENTUK PENILAIAN | M1: TIPE PENILAIAN | N1: TEMA | O1: TOPIK | P1: PROYEK | Q1: SKILL | R1: SUB SKILL | S1: KODE MATERI | T1: NO TP | U1: KETERANGAN TP | V1: NO MATERI | W1: KETERANGAN MATERI | X1: MATERI KELAS | Y1: FASE | Z1: KKM | AA1: NILAI | AB1: KETUNTASAN | AC1: MAPEL | AD1: NAMA GURU | AE1: Mapel TDU | AF1: Nilai2 | AG1: Predikat | AH1: MatKls | AI1: Predikat Krktr | AJ1: Wk# | AK1: IQ Status
A2: 1 | B2: 242510013 | C2: 11A | D2: Yohanes Bagau | E2: Intan Jaya | F2: 46036 | G2: 14 | H2: Jan | I2: 26 | J2: Teori | K2: Kognitif Formatif | L2: Observ | M2: Real | N2: Entrepreneur | O2: Product development | P2: Pengolahan Kopi atau Tepung | Q2: Product development | R2: Pengembangan produk inovasi | S2: F11.01.01 | T2: 1 | U2: Membentuk komunitas yang bertumbuh dalam pengenalan akan Firman Tuhan dan meyediakan ruang untuk saling membangun, berbagi serta mendalami Iman | V2: 01.01 | W2: Gaya hidup saleh di tengah budaya hedonisme | X2: K11 | Y2: F | Z2: 65 | AA2: 0 | AB2: Tidak tuntas | AC2: Agama Katolik | AD2: Fenty Yunia Vianarika, S.Pd., Gr. | AE2: =IF(AF2="","",VLOOKUP(AC2,mapel!$A$2:$B$42,2,FALSE)) | AF2: =IF(AA2=0, "",IF(AA2 = 0.1, 0,AA2)) | AG2: =IF(AF2="","",IF(AF2>90,"Sangat baik",IF(AF2>79,"Baik",IF(AF2>=pub_gid_0_single_true_output_csv[[#This Row],[KKM]],"Cukup","Kurang")))) | AH2: =IF(AG2="","",VALUE(RIGHT(X2,2))) | AI2: =IF(OR(J2<>"Karakter",pub_gid_0_single_true_output_csv[[#This Row],[Nilai2]]=""),"",IF(AF2>89,"Sangat baik",IF(AF2>79,"Baik",IF(AF2>69,"Cukup",IF(AF2>59,"Kurang","Sangat kurang"))))) | AJ2: =IF(AF2="","",CONCATENATE("Wk.",WEEKNUM(F2,2))) | AK2: =IF(pub_gid_0_single_true_output_csv[[#This Row],[Nilai2]]="","",VLOOKUP(pub_gid_0_single_true_output_csv[[#This Row],[NAMA]],Table7[],3,FALSE))
A3: 2 | B3: 242510013 | C3: 11A | D3: Yohanes Bagau | E3: Intan Jaya | F3: 46043 | G3: 21 | H3: Jan | I3: 26 | J3: Teori | K3: Kognitif Formatif | L3: Observ | M3: Real | N3: Entrepreneur | O3: Product development | P3: Pengolahan Kopi atau Tepung | Q3: Product development | R3: Pengembangan produk inovasi | S3: F11.01.02 | T3: 1 | U3: Membentuk komunitas yang bertumbuh dalam pengenalan akan Firman Tuhan dan meyediakan ruang untuk saling membangun, berbagi serta mendalami Iman | V3: 01.02 | W3: Peran Kristen di media sosial | X3: K11 | Y3: F | Z3: 65 | AA3: 0 | AB3: Tidak tuntas | AC3: Agama Katolik | AD3: Fenty Yunia Vianarika, S.Pd., Gr. | AE3: =IF(AF3="","",VLOOKUP(AC3,mapel!$A$2:$B$42,2,FALSE)) | AF3: =IF(AA3=0, "",IF(AA3 = 0.1, 0,AA3)) | AG3: =IF(AF3="","",IF(AF3>90,"Sangat baik",IF(AF3>79,"Baik",IF(AF3>=pub_gid_0_single_true_output_csv[[#This Row],[KKM]],"Cukup","Kurang")))) | AH3: =IF(AG3="","",VALUE(RIGHT(X3,2))) | AI3: =IF(OR(J3<>"Karakter",pub_gid_0_single_true_output_csv[[#This Row],[Nilai2]]=""),"",IF(AF3>89,"Sangat baik",IF(AF3>79,"Baik",IF(AF3>69,"Cukup",IF(AF3>59,"Kurang","Sangat kurang"))))) | AJ3: =IF(AF3="","",CONCATENATE("Wk.",WEEKNUM(F3,2))) | AK3: =IF(pub_gid_0_single_true_output_csv[[#This Row],[Nilai2]]="","",VLOOKUP(pub_gid_0_single_true_output_csv[[#This Row],[NAMA]],Table7[],3,FALSE))
A4: 3 | B4: 242510013 | C4: 11A | D4: Yohanes Bagau | E4: Intan Jaya | F4: 46050 | G4: 28 | H4: Jan | I4: 26 | J4: Skill | K4: Evaluasi & Kalibrasi | L4: Observ | M4: Real | N4: Entrepreneur | O4: Product development | P4: Pengolahan Kopi atau Tepung | Q4: Product development | R4: Pengembangan produk inovasi | S4: F11.01.03 | T4: 1 | U4: Membentuk komunitas yang bertumbuh dalam pengenalan akan Firman Tuhan dan meyediakan ruang untuk saling membangun, berbagi serta mendalami Iman | V4: 01.03 | W4: Dunia vs transformasi rohani | X4: K11 | Y4: F | Z4: 65 | AA4: 0 | AB4: Tidak tuntas | AC4: Agama Katolik | AD4: Fenty Yunia Vianarika, S.Pd., Gr. | AE4: =IF(AF4="","",VLOOKUP(AC4,mapel!$A$2:$B$42,2,FALSE)) | AF4: =IF(AA4=0, "",IF(AA4 = 0.1, 0,AA4)) | AG4: =IF(AF4="","",IF(AF4>90,"Sangat baik",IF(AF4>79,"Baik",IF(AF4>=pub_gid_0_single_true_output_csv[[#This Row],[KKM]],"Cukup","Kurang")))) | AH4: =IF(AG4="","",VALUE(RIGHT(X4,2))) | AI4: =IF(OR(J4<>"Karakter",pub_gid_0_single_true_output_csv[[#This Row],[Nilai2]]=""),"",IF(AF4>89,"Sangat baik",IF(AF4>79,"Baik",IF(AF4>69,"Cukup",IF(AF4>59,"Kurang","Sangat kurang"))))) | AJ4: =IF(AF4="","",CONCATENATE("Wk.",WEEKNUM(F4,2))) | AK4: =IF(pub_gid_0_single_true_output_csv[[#This Row],[Nilai2]]="","",VLOOKUP(pub_gid_0_single_true_output_csv[[#This Row],[NAMA]],Table7[],3,FALSE))
A5: 4 | B5: 242510013 | C5: 11A | D5: Yohanes Bagau | E5: Intan Jaya | F5: 46057 | G5: 04 | H5: Feb | I5: 26 | J5: Teori | K5: Kognitif Formatif | L5: Observ | M5: Real | N5: Entrepreneur | O5: Product development | P5: Pengolahan Kopi atau Tepung | Q5: Product development | R5: Pengembangan produk inovasi | S5: F11.01.04 | T5: 1 | U5: Membentuk komunitas yang bertumbuh dalam pengenalan akan Firman Tuhan dan meyediakan ruang untuk saling membangun, berbagi serta mendalami Iman | V5: 01.04 | W5: Isu lingkungan & peran manusia | X5: K11 | Y5: F | Z5: 65 | AA5: 0 | AB5: Tidak tuntas | AC5: Agama Katolik | AD5: Fenty Yunia Vianarika, S.Pd., Gr. | AE5: =IF(AF5="","",VLOOKUP(AC5,mapel!$A$2:$B$42,2,FALSE)) | AF5: =IF(AA5=0, "",IF(AA5 = 0.1, 0,AA5)) | AG5: =IF(AF5="","",IF(AF5>90,"Sangat baik",IF(AF5>79,"Baik",IF(AF5>=pub_gid_0_single_true_output_csv[[#This Row],[KKM]],"Cukup","Kurang")))) | AH5: =IF(AG5="","",VALUE(RIGHT(X5,2))) | AI5: =IF(OR(J5<>"Karakter",pub_gid_0_single_true_output_csv[[#This Row],[Nilai2]]=""),"",IF(AF5>89,"Sangat baik",IF(AF5>79,"Baik",IF(AF5>69,"Cukup",IF(AF5>59,"Kurang","Sangat kurang"))))) | AJ5: =IF(AF5="","",CONCATENATE("Wk.",WEEKNUM(F5,2))) | AK5: =IF(pub_gid_0_single_true_output_csv[[#This Row],[Nilai2]]="","",VLOOKUP(pub_gid_0_single_true_output_csv[[#This Row],[NAMA]],Table7[],3,FALSE))
A6: 5 | B6: 242510011 | C6: 11A | D6: Roison Sondegau | E6: Intan Jaya | F6: 46036 | G6: 14 | H6: Jan | I6: 26 | J6: Teori | K6: Kognitif Formatif | L6: Observ | M6: Real | N6: Entrepreneur | O6: Product development | P6: Pengolahan Kopi atau Tepung | Q6: Product development | R6: Pengembangan produk inovasi | S6: F11.01.01 | T6: 1 | U6: Membentuk komunitas yang bertumbuh dalam pengenalan akan Firman Tuhan dan meyediakan ruang untuk saling membangun, berbagi serta mendalami Iman | V6: 01.01 | W6: Gaya hidup saleh di tengah budaya hedonisme | X6: K11 | Y6: F | Z6: 65 | AA6: 70 | AB6: Tuntas | AC6: Agama Katolik | AD6: Fenty Yunia Vianarika, S.Pd., Gr. | AE6: =IF(AF6="","",VLOOKUP(AC6,mapel!$A$2:$B$42,2,FALSE)) -> A.Katolik | AF6: =IF(AA6=0, "",IF(AA6 = 0.1, 0,AA6)) -> 70 | AG6: =IF(AF6="","",IF(AF6>90,"Sangat baik",IF(AF6>79,"Baik",IF(AF6>=pub_gid_0_single_true_output_csv[[#This Row],[KKM]],"Cukup","Kurang")))) -> Cukup | AH6: =IF(AG6="","",VALUE(RIGHT(X6,2))) -> 11 | AI6: =IF(OR(J6<>"Karakter",pub_gid_0_single_true_output_csv[[#This Row],[Nilai2]]=""),"",IF(AF6>89,"Sangat baik",IF(AF6>79,"Baik",IF(AF6>69,"Cukup",IF(AF6>59,"Kurang","Sangat kurang"))))) | AJ6: =IF(AF6="","",CONCATENATE("Wk.",WEEKNUM(F6,2))) -> Wk.3 | AK6: =IF(pub_gid_0_single_true_output_csv[[#This Row],[Nilai2]]="","",VLOOKUP(pub_gid_0_single_true_output_csv[[#This Row],[NAMA]],Table7[],3,FALSE)) -> Extremely low
A7: 6 | B7: 242510011 | C7: 11A | D7: Roison Sondegau | E7: Intan Jaya | F7: 46043 | G7: 21 | H7: Jan | I7: 26 | J7: Teori | K7: Kognitif Formatif | L7: Observ | M7: Real | N7: Entrepreneur | O7: Product development | P7: Pengolahan Kopi atau Tepung | Q7: Product development | R7: Pengembangan produk inovasi | S7: F11.01.02 | T7: 1 | U7: Membentuk komunitas yang bertumbuh dalam pengenalan akan Firman Tuhan dan meyediakan ruang untuk saling membangun, berbagi serta mendalami Iman | V7: 01.02 | W7: Peran Kristen di media sosial | X7: K11 | Y7: F | Z7: 65 | AA7: 75 | AB7: Tuntas | AC7: Agama Katolik | AD7: Fenty Yunia Vianarika, S.Pd., Gr. | AE7: =IF(AF7="","",VLOOKUP(AC7,mapel!$A$2:$B$42,2,FALSE)) -> A.Katolik | AF7: =IF(AA7=0, "",IF(AA7 = 0.1, 0,AA7)) -> 75 | AG7: =IF(AF7="","",IF(AF7>90,"Sangat baik",IF(AF7>79,"Baik",IF(AF7>=pub_gid_0_single_true_output_csv[[#This Row],[KKM]],"Cukup","Kurang")))) -> Cukup | AH7: =IF(AG7="","",VALUE(RIGHT(X7,2))) -> 11 | AI7: =IF(OR(J7<>"Karakter",pub_gid_0_single_true_output_csv[[#This Row],[Nilai2]]=""),"",IF(AF7>89,"Sangat baik",IF(AF7>79,"Baik",IF(AF7>69,"Cukup",IF(AF7>59,"Kurang","Sangat kurang"))))) | AJ7: =IF(AF7="","",CONCATENATE("Wk.",WEEKNUM(F7,2))) -> Wk.4 | AK7: =IF(pub_gid_0_single_true_output_csv[[#This Row],[Nilai2]]="","",VLOOKUP(pub_gid_0_single_true_output_csv[[#This Row],[NAMA]],Table7[],3,FALSE)) -> Extremely low
A8: 7 | B8: 242510011 | C8: 11A | D8: Roison Sondegau | E8: Intan Jaya | F8: 46050 | G8: 28 | H8: Jan | I8: 26 | J8: Skill | K8: Evaluasi & Kalibrasi | L8: Observ | M8: Real | N8: Entrepreneur | O8: Product development | P8: Pengolahan Kopi atau Tepung | Q8: Product development | R8: Pengembangan produk inovasi | S8: F11.01.03 | T8: 1 | U8: Membentuk komunitas yang bertumbuh dalam pengenalan akan Firman Tuhan dan meyediakan ruang untuk saling membangun, berbagi serta mendalami Iman | V8: 01.03 | W8: Dunia vs transformasi rohani | X8: K11 | Y8: F | Z8: 65 | AA8: 79 | AB8: Tuntas | AC8: Agama Katolik | AD8: Fenty Yunia Vianarika, S.Pd., Gr. | AE8: =IF(AF8="","",VLOOKUP(AC8,mapel!$A$2:$B$42,2,FALSE)) -> A.Katolik | AF8: =IF(AA8=0, "",IF(AA8 = 0.1, 0,AA8)) -> 79 | AG8: =IF(AF8="","",IF(AF8>90,"Sangat baik",IF(AF8>79,"Baik",IF(AF8>=pub_gid_0_single_true_output_csv[[#This Row],[KKM]],"Cukup","Kurang")))) -> Cukup | AH8: =IF(AG8="","",VALUE(RIGHT(X8,2))) -> 11 | AI8: =IF(OR(J8<>"Karakter",pub_gid_0_single_true_output_csv[[#This Row],[Nilai2]]=""),"",IF(AF8>89,"Sangat baik",IF(AF8>79,"Baik",IF(AF8>69,"Cukup",IF(AF8>59,"Kurang","Sangat kurang"))))) | AJ8: =IF(AF8="","",CONCATENATE("Wk.",WEEKNUM(F8,2))) -> Wk.5 | AK8: =IF(pub_gid_0_single_true_output_csv[[#This Row],[Nilai2]]="","",VLOOKUP(pub_gid_0_single_true_output_csv[[#This Row],[NAMA]],Table7[],3,FALSE)) -> Extremely low
A9: 8 | B9: 242510011 | C9: 11A | D9: Roison Sondegau | E9: Intan Jaya | F9: 46057 | G9: 04 | H9: Feb | I9: 26 | J9: Teori | K9: Kognitif Formatif | L9: Observ | M9: Real | N9: Entrepreneur | O9: Product development | P9: Pengolahan Kopi atau Tepung | Q9: Product development | R9: Pengembangan produk inovasi | S9: F11.01.04 | T9: 1 | U9: Membentuk komunitas yang bertumbuh dalam pengenalan akan Firman Tuhan dan meyediakan ruang untuk saling membangun, berbagi serta mendalami Iman | V9: 01.04 | W9: Isu lingkungan & peran manusia | X9: K11 | Y9: F | Z9: 65 | AA9: 80 | AB9: Tuntas | AC9: Agama Katolik | AD9: Fenty Yunia Vianarika, S.Pd., Gr. | AE9: =IF(AF9="","",VLOOKUP(AC9,mapel!$A$2:$B$42,2,FALSE)) -> A.Katolik | AF9: =IF(AA9=0, "",IF(AA9 = 0.1, 0,AA9)) -> 80 | AG9: =IF(AF9="","",IF(AF9>90,"Sangat baik",IF(AF9>79,"Baik",IF(AF9>=pub_gid_0_single_true_output_csv[[#This Row],[KKM]],"Cukup","Kurang")))) -> Baik | AH9: =IF(AG9="","",VALUE(RIGHT(X9,2))) -> 11 | AI9: =IF(OR(J9<>"Karakter",pub_gid_0_single_true_output_csv[[#This Row],[Nilai2]]=""),"",IF(AF9>89,"Sangat baik",IF(AF9>79,"Baik",IF(AF9>69,"Cukup",IF(AF9>59,"Kurang","Sangat kurang"))))) | AJ9: =IF(AF9="","",CONCATENATE("Wk.",WEEKNUM(F9,2))) -> Wk.6 | AK9: =IF(pub_gid_0_single_true_output_csv[[#This Row],[Nilai2]]="","",VLOOKUP(pub_gid_0_single_true_output_csv[[#This Row],[NAMA]],Table7[],3,FALSE)) -> Extremely low
A10: 9 | B10: 242510010 | C10: 11A | D10: Onance Mbaguau | E10: Intan Jaya | F10: 46036 | G10: 14 | H10: Jan | I10: 26 | J10: Teori | K10: Kognitif Formatif | L10: Observ | M10: Real | N10: Entrepreneur | O10: Product development | P10: Pengolahan Kopi atau Tepung | Q10: Product development | R10: Pengembangan produk inovasi | S10: F11.01.01 | T10: 1 | U10: Membentuk komunitas yang bertumbuh dalam pengenalan akan Firman Tuhan dan meyediakan ruang untuk saling membangun, berbagi serta mendalami Iman | V10: 01.01 | W10: Gaya hidup saleh di tengah budaya hedonisme | X10: K11 | Y10: F | Z10: 65 | AA10: 70 | AB10: Tuntas | AC10: Agama Katolik | AD10: Fenty Yunia Vianarika, S.Pd., Gr. | AE10: =IF(AF10="","",VLOOKUP(AC10,mapel!$A$2:$B$42,2,FALSE)) -> A.Katolik | AF10: =IF(AA10=0, "",IF(AA10 = 0.1, 0,AA10)) -> 70 | AG10: =IF(AF10="","",IF(AF10>90,"Sangat baik",IF(AF10>79,"Baik",IF(AF10>=pub_gid_0_single_true_output_csv[[#This Row],[KKM]],"Cukup","Kurang")))) -> Cukup | AH10: =IF(AG10="","",VALUE(RIGHT(X10,2))) -> 11 | AI10: =IF(OR(J10<>"Karakter",pub_gid_0_single_true_output_csv[[#This Row],[Nilai2]]=""),"",IF(AF10>89,"Sangat baik",IF(AF10>79,"Baik",IF(AF10>69,"Cukup",IF(AF10>59,"Kurang","Sangat kurang"))))) | AJ10: =IF(AF10="","",CONCATENATE("Wk.",WEEKNUM(F10,2))) -> Wk.3 | AK10: =IF(pub_gid_0_single_true_output_csv[[#This Row],[Nilai2]]="","",VLOOKUP(pub_gid_0_single_true_output_csv[[#This Row],[NAMA]],Table7[],3,FALSE)) -> Average
A11: 10 | B11: 242510010 | C11: 11A | D11: Onance Mbaguau | E11: Intan Jaya | F11: 46043 | G11: 21 | H11: Jan | I11: 26 | J11: Teori | K11: Kognitif Formatif | L11: Observ | M11: Real | N11: Entrepreneur | O11: Product development | P11: Pengolahan Kopi atau Tepung | Q11: Product development | R11: Pengembangan produk inovasi | S11: F11.01.02 | T11: 1 | U11: Membentuk komunitas yang bertumbuh dalam pengenalan akan Firman Tuhan dan meyediakan ruang untuk saling membangun, berbagi serta mendalami Iman | V11: 01.02 | W11: Peran Kristen di media sosial | X11: K11 | Y11: F | Z11: 65 | AA11: 75 | AB11: Tuntas | AC11: Agama Katolik | AD11: Fenty Yunia Vianarika, S.Pd., Gr. | AE11: =IF(AF11="","",VLOOKUP(AC11,mapel!$A$2:$B$42,2,FALSE)) -> A.Katolik | AF11: =IF(AA11=0, "",IF(AA11 = 0.1, 0,AA11)) -> 75 | AG11: =IF(AF11="","",IF(AF11>90,"Sangat baik",IF(AF11>79,"Baik",IF(AF11>=pub_gid_0_single_true_output_csv[[#This Row],[KKM]],"Cukup","Kurang")))) -> Cukup | AH11: =IF(AG11="","",VALUE(RIGHT(X11,2))) -> 11 | AI11: =IF(OR(J11<>"Karakter",pub_gid_0_single_true_output_csv[[#This Row],[Nilai2]]=""),"",IF(AF11>89,"Sangat baik",IF(AF11>79,"Baik",IF(AF11>69,"Cukup",IF(AF11>59,"Kurang","Sangat kurang"))))) | AJ11: =IF(AF11="","",CONCATENATE("Wk.",WEEKNUM(F11,2))) -> Wk.4 | AK11: =IF(pub_gid_0_single_true_output_csv[[#This Row],[Nilai2]]="","",VLOOKUP(pub_gid_0_single_true_output_csv[[#This Row],[NAMA]],Table7[],3,FALSE)) -> Average
A12: 11 | B12: 242510010 | C12: 11A | D12: Onance Mbaguau | E12: Intan Jaya | F12: 46050 | G12: 28 | H12: Jan | I12: 26 | J12: Skill | K12: Evaluasi & Kalibrasi | L12: Observ | M12: Real | N12: Entrepreneur | O12: Product development | P12: Pengolahan Kopi atau Tepung | Q12: Product development | R12: Pengembangan produk inovasi | S12: F11.01.03 | T12: 1 | U12: Membentuk komunitas yang bertumbuh dalam pengenalan akan Firman Tuhan dan meyediakan ruang untuk saling membangun, berbagi serta mendalami Iman | V12: 01.03 | W12: Dunia vs transformasi rohani | X12: K11 | Y12: F | Z12: 65 | AA12: 80 | AB12: Tuntas | AC12: Agama Katolik | AD12: Fenty Yunia Vianarika, S.Pd., Gr. | AE12: =IF(AF12="","",VLOOKUP(AC12,mapel!$A$2:$B$42,2,FALSE)) -> A.Katolik | AF12: =IF(AA12=0, "",IF(AA12 = 0.1, 0,AA12)) -> 80 | AG12: =IF(AF12="","",IF(AF12>90,"Sangat baik",IF(AF12>79,"Baik",IF(AF12>=pub_gid_0_single_true_output_csv[[#This Row],[KKM]],"Cukup","Kurang")))) -> Baik | AH12: =IF(AG12="","",VALUE(RIGHT(X12,2))) -> 11 | AI12: =IF(OR(J12<>"Karakter",pub_gid_0_single_true_output_csv[[#This Row],[Nilai2]]=""),"",IF(AF12>89,"Sangat baik",IF(AF12>79,"Baik",IF(AF12>69,"Cukup",IF(AF12>59,"Kurang","Sangat kurang"))))) | AJ12: =IF(AF12="","",CONCATENATE("Wk.",WEEKNUM(F12,2))) -> Wk.5 | AK12: =IF(pub_gid_0_single_true_output_csv[[#This Row],[Nilai2]]="","",VLOOKUP(pub_gid_0_single_true_output_csv[[#This Row],[NAMA]],Table7[],3,FALSE)) -> Average
A13: 12 | B13: 242510010 | C13: 11A | D13: Onance Mbaguau | E13: Intan Jaya | F13: 46057 | G13: 04 | H13: Feb | I13: 26 | J13: Teori | K13: Kognitif Formatif | L13: Observ | M13: Real | N13: Entrepreneur | O13: Product development | P13: Pengolahan Kopi atau Tepung | Q13: Product development | R13: Pengembangan produk inovasi | S13: F11.01.04 | T13: 1 | U13: Membentuk komunitas yang bertumbuh dalam pengenalan akan Firman Tuhan dan meyediakan ruang untuk saling membangun, berbagi serta mendalami Iman | V13: 01.04 | W13: Isu lingkungan & peran manusia | X13: K11 | Y13: F | Z13: 65 | AA13: 75 | AB13: Tuntas | AC13: Agama Katolik | AD13: Fenty Yunia Vianarika, S.Pd., Gr. | AE13: =IF(AF13="","",VLOOKUP(AC13,mapel!$A$2:$B$42,2,FALSE)) -> A.Katolik | AF13: =IF(AA13=0, "",IF(AA13 = 0.1, 0,AA13)) -> 75 | AG13: =IF(AF13="","",IF(AF13>90,"Sangat baik",IF(AF13>79,"Baik",IF(AF13>=pub_gid_0_single_true_output_csv[[#This Row],[KKM]],"Cukup","Kurang")))) -> Cukup | AH13: =IF(AG13="","",VALUE(RIGHT(X13,2))) -> 11 | AI13: =IF(OR(J13<>"Karakter",pub_gid_0_single_true_output_csv[[#This Row],[Nilai2]]=""),"",IF(AF13>89,"Sangat baik",IF(AF13>79,"Baik",IF(AF13>69,"Cukup",IF(AF13>59,"Kurang","Sangat kurang"))))) | AJ13: =IF(AF13="","",CONCATENATE("Wk.",WEEKNUM(F13,2))) -> Wk.6 | AK13: =IF(pub_gid_0_single_true_output_csv[[#This Row],[Nilai2]]="","",VLOOKUP(pub_gid_0_single_true_output_csv[[#This Row],[NAMA]],Table7[],3,FALSE)) -> Average
... A529: 528 | B529: 242510012 | C529: 11A | D529: Wenes Tapani | E529: Intan Jaya | F529: 46071 | G529: 18 | H529: Feb | I529: 26 | J529: Teori | K529: Kognitif Formatif | L529: Projek | M529: Real | N529: Entrepreneur | O529: Product development | P529: Pengolahan Kopi atau Tepung | Q529: Product development | R529: Pengembangan produk inovasi | S529: F11.02.01 | T529: 2 | U529: mengargumentasikan yang berkaitan dengan pengembangan produk untuk peningkatan taraf perekonomian masyarakat melalui karya tulis ilmiah | V529: 02.01 | W529: Exposition Text | X529: K11 | Y529: F | Z529: 65 | AA529: 70 | AB529: Tuntas | AC529: Bahasa Inggris | AD529: Fenty Yunia Vianarika, S.Pd., Gr. | AE529: =IF(AF529="","",VLOOKUP(AC529,mapel!$A$2:$B$42,2,FALSE)) -> B.Ing | AF529: =IF(AA529=0, "",IF(AA529 = 0.1, 0,AA529)) -> 70 | AG529: =IF(AF529="","",IF(AF529>90,"Sangat baik",IF(AF529>79,"Baik",IF(AF529>=pub_gid_0_single_true_output_csv[[#This Row],[KKM]],"Cukup","Kurang")))) -> Cukup | AH529: =IF(AG529="","",VALUE(RIGHT(X529,2))) -> 11 | AI529: =IF(OR(J529<>"Karakter",pub_gid_0_single_true_output_csv[[#This Row],[Nilai2]]=""),"",IF(AF529>89,"Sangat baik",IF(AF529>79,"Baik",IF(AF529>69,"Cukup",IF(AF529>59,"Kurang","Sangat kurang"))))) | AJ529: =IF(AF529="","",CONCATENATE("Wk.",WEEKNUM(F529,2))) -> Wk.8 | AK529: =IF(pub_gid_0_single_true_output_csv[[#This Row],[Nilai2]]="","",VLOOKUP(pub_gid_0_single_true_output_csv[[#This Row],[NAMA]],Table7[],3,FALSE)) -> Average
A530: 529 | B530: #N/A | C530: #VALUE! | D530: #VALUE! | E530: #VALUE! | G530: ,,,,,,,,,,,, | H530: ,,,,,,,,,,,, | I530: ,,,,,,,,,,,, | J530: ,,,,,,,,,,,, | K530: |||||||||||| | L530: |||||||||||| | M530: ,,,,,,,,,,,, | Q530: N | R530: N | S530: ,,,,,,,,,,,, | V530: ,,,,, | W530: #N/A | X530: ,,,,,,,,,,,, | Y530: , | Z530: 65 | AB530: #REF! | AC530: Bahasa Sunda | AD530: Fenty Yunia Vianarika, S.Pd., Gr. | AE530: =IF(AF530="","",VLOOKUP(AC530,mapel!$A$2:$B$42,2,FALSE)) | AF530: =IF(AA530=0, "",IF(AA530 = 0.1, 0,AA530)) | AG530: =IF(AF530="","",IF(AF530>90,"Sangat baik",IF(AF530>79,"Baik",IF(AF530>=pub_gid_0_single_true_output_csv[[#This Row],[KKM]],"Cukup","Kurang")))) | AH530: =IF(AG530="","",VALUE(RIGHT(X530,2))) | AI530: =IF(OR(J530<>"Karakter",pub_gid_0_single_true_output_csv[[#This Row],[Nilai2]]=""),"",IF(AF530>89,"Sangat baik",IF(AF530>79,"Baik",IF(AF530>69,"Cukup",IF(AF530>59,"Kurang","Sangat kurang"))))) | AJ530: =IF(AF530="","",CONCATENATE("Wk.",WEEKNUM(F530,2))) | AK530: =IF(pub_gid_0_single_true_output_csv[[#This Row],[Nilai2]]="","",VLOOKUP(pub_gid_0_single_true_output_csv[[#This Row],[NAMA]],Table7[],3,FALSE))
A531: 530 | B531: 242510001 | C531: 11A | D531: Apia Miagoni | E531: Intan Jaya | F531: 46041 | G531: 19 | H531: Jan | I531: 26 | J531: Teori | K531: Kognitif Formatif | L531: Latihan | M531: Real | N531: Entrepreneur | O531: Product development | P531: Pengolahan Kopi atau Tepung | Q531: Product development | R531: Pengembangan produk inovasi | S531: F11.03.01 | T531: 3 | U531: Pemahaman nutrisi yang terkandung pada makanan terutama pada kopi dan singkong | V531: 03.01 | W531: Nutrisi pada Makanan | X531: K11 | Y531: F | Z531: 65 | AA531: 100 | AB531: Tuntas | AC531: Biologi | AD531: Eka Dewi Sriyani, S.Pd., M.Si., Gr. | AE531: =IF(AF531="","",VLOOKUP(AC531,mapel!$A$2:$B$42,2,FALSE)) -> Biologi | AF531: =IF(AA531=0, "",IF(AA531 = 0.1, 0,AA531)) -> 100 | AG531: =IF(AF531="","",IF(AF531>90,"Sangat baik",IF(AF531>79,"Baik",IF(AF531>=pub_gid_0_single_true_output_csv[[#This Row],[KKM]],"Cukup","Kurang")))) -> Sangat baik | AH531: =IF(AG531="","",VALUE(RIGHT(X531,2))) -> 11 | AI531: =IF(OR(J531<>"Karakter",pub_gid_0_single_true_output_csv[[#This Row],[Nilai2]]=""),"",IF(AF531>89,"Sangat baik",IF(AF531>79,"Baik",IF(AF531>69,"Cukup",IF(AF531>59,"Kurang","Sangat kurang"))))) | AJ531: =IF(AF531="","",CONCATENATE("Wk.",WEEKNUM(F531,2))) -> Wk.4 | AK531: =IF(pub_gid_0_single_true_output_csv[[#This Row],[Nilai2]]="","",VLOOKUP(pub_gid_0_single_true_output_csv[[#This Row],[NAMA]],Table7[],3,FALSE)) -> Average
A532: 531 | B532: 242510007 | C532: 11A | D532: Jupiten Bagau | E532: Intan Jaya | F532: 46041 | G532: 19 | H532: Jan | I532: 26 | J532: Teori | K532: Kognitif Formatif | L532: Latihan | M532: Real | N532: Entrepreneur | O532: Product development | P532: Pengolahan Kopi atau Tepung | Q532: Product development | R532: Pengembangan produk inovasi | S532: F11.03.01 | T532: 3 | U532: Pemahaman nutrisi yang terkandung pada makanan terutama pada kopi dan singkong | V532: 03.01 | W532: Nutrisi pada Makanan | X532: K11 | Y532: F | Z532: 65 | AA532: 40 | AB532: Tidak tuntas | AC532: Biologi | AD532: Eka Dewi Sriyani, S.Pd., M.Si., Gr. | AE532: =IF(AF532="","",VLOOKUP(AC532,mapel!$A$2:$B$42,2,FALSE)) -> Biologi | AF532: =IF(AA532=0, "",IF(AA532 = 0.1, 0,AA532)) -> 40 | AG532: =IF(AF532="","",IF(AF532>90,"Sangat baik",IF(AF532>79,"Baik",IF(AF532>=pub_gid_0_single_true_output_csv[[#This Row],[KKM]],"Cukup","Kurang")))) -> Kurang | AH532: =IF(AG532="","",VALUE(RIGHT(X532,2))) -> 11 | AI532: =IF(OR(J532<>"Karakter",pub_gid_0_single_true_output_csv[[#This Row],[Nilai2]]=""),"",IF(AF532>89,"Sangat baik",IF(AF532>79,"Baik",IF(AF532>69,"Cukup",IF(AF532>59,"Kurang","Sangat kurang"))))) | AJ532: =IF(AF532="","",CONCATENATE("Wk.",WEEKNUM(F532,2))) -> Wk.4 | AK532: =IF(pub_gid_0_single_true_output_csv[[#This Row],[Nilai2]]="","",VLOOKUP(pub_gid_0_single_true_output_csv[[#This Row],[NAMA]],Table7[],3,FALSE)) -> Superior
A533: 532 | B533: 242510008 | C533: 11A | D533: Lince Tigi | E533: Dogiyai | F533: 46041 | G533: 19 | H533: Jan | I533: 26 | J533: Teori | K533: Kognitif Formatif | L533: Latihan | M533: Real | N533: Entrepreneur | O533: Product development | P533: Pengolahan Kopi atau Tepung | Q533: Product development | R533: Pengembangan produk inovasi | S533: F11.03.01 | T533: 3 | U533: Pemahaman nutrisi yang terkandung pada makanan terutama pada kopi dan singkong | V533: 03.01 | W533: Nutrisi pada Makanan | X533: K11 | Y533: F | Z533: 65 | AA533: 89 | AB533: Tuntas | AC533: Biologi | AD533: Eka Dewi Sriyani, S.Pd., M.Si., Gr. | AE533: =IF(AF533="","",VLOOKUP(AC533,mapel!$A$2:$B$42,2,FALSE)) -> Biologi | AF533: =IF(AA533=0, "",IF(AA533 = 0.1, 0,AA533)) -> 89 | AG533: =IF(AF533="","",IF(AF533>90,"Sangat baik",IF(AF533>79,"Baik",IF(AF533>=pub_gid_0_single_true_output_csv[[#This Row],[KKM]],"Cukup","Kurang")))) -> Baik | AH533: =IF(AG533="","",VALUE(RIGHT(X533,2))) -> 11 | AI533: =IF(OR(J533<>"Karakter",pub_gid_0_single_true_output_csv[[#This Row],[Nilai2]]=""),"",IF(AF533>89,"Sangat baik",IF(AF533>79,"Baik",IF(AF533>69,"Cukup",IF(AF533>59,"Kurang","Sangat kurang"))))) | AJ533: =IF(AF533="","",CONCATENATE("Wk.",WEEKNUM(F533,2))) -> Wk.4 | AK533: =IF(pub_gid_0_single_true_output_csv[[#This Row],[Nilai2]]="","",VLOOKUP(pub_gid_0_single_true_output_csv[[#This Row],[NAMA]],Table7[],3,FALSE)) -> High average
A534: 533 | B534: 242510013 | C534: 11A | D534: Yohanes Bagau | E534: Intan Jaya | F534: 46041 | G534: 19 | H534: Jan | I534: 26 | J534: Teori | K534: Kognitif Formatif | L534: Latihan | M534: Real | N534: Entrepreneur | O534: Product development | P534: Pengolahan Kopi atau Tepung | Q534: Product development | R534: Pengembangan produk inovasi | S534: F11.03.01 | T534: 3 | U534: Pemahaman nutrisi yang terkandung pada makanan terutama pada kopi dan singkong | V534: 03.01 | W534: Nutrisi pada Makanan | X534: K11 | Y534: F | Z534: 65 | AA534: 40 | AB534: Tidak tuntas | AC534: Biologi | AD534: Eka Dewi Sriyani, S.Pd., M.Si., Gr. | AE534: =IF(AF534="","",VLOOKUP(AC534,mapel!$A$2:$B$42,2,FALSE)) -> Biologi | AF534: =IF(AA534=0, "",IF(AA534 = 0.1, 0,AA534)) -> 40 | AG534: =IF(AF534="","",IF(AF534>90,"Sangat baik",IF(AF534>79,"Baik",IF(AF534>=pub_gid_0_single_true_output_csv[[#This Row],[KKM]],"Cukup","Kurang")))) -> Kurang | AH534: =IF(AG534="","",VALUE(RIGHT(X534,2))) -> 11 | AI534: =IF(OR(J534<>"Karakter",pub_gid_0_single_true_output_csv[[#This Row],[Nilai2]]=""),"",IF(AF534>89,"Sangat baik",IF(AF534>79,"Baik",IF(AF534>69,"Cukup",IF(AF534>59,"Kurang","Sangat kurang"))))) | AJ534: =IF(AF534="","",CONCATENATE("Wk.",WEEKNUM(F534,2))) -> Wk.4 | AK534: =IF(pub_gid_0_single_true_output_csv[[#This Row],[Nilai2]]="","",VLOOKUP(pub_gid_0_single_true_output_csv[[#This Row],[NAMA]],Table7[],3,FALSE)) -> #N/A
A535: 534 | B535: 242510014 | C535: 11A | D535: Yoas Bagau | E535: Inta jaya | F535: 46041 | G535: 19 | H535: Jan | I535: 26 | J535: Teori | K535: Kognitif Formatif | L535: Latihan | M535: Real | N535: Entrepreneur | O535: Product development | P535: Pengolahan Kopi atau Tepung | Q535: Product development | R535: Pengembangan produk inovasi | S535: F11.03.01 | T535: 3 | U535: Pemahaman nutrisi yang terkandung pada makanan terutama pada kopi dan singkong | V535: 03.01 | W535: Nutrisi pada Makanan | X535: K11 | Y535: F | Z535: 65 | AA535: 99 | AB535: Tuntas | AC535: Biologi | AD535: Eka Dewi Sriyani, S.Pd., M.Si., Gr. | AE535: =IF(AF535="","",VLOOKUP(AC535,mapel!$A$2:$B$42,2,FALSE)) -> Biologi | AF535: =IF(AA535=0, "",IF(AA535 = 0.1, 0,AA535)) -> 99 | AG535: =IF(AF535="","",IF(AF535>90,"Sangat baik",IF(AF535>79,"Baik",IF(AF535>=pub_gid_0_single_true_output_csv[[#This Row],[KKM]],"Cukup","Kurang")))) -> Sangat baik | AH535: =IF(AG535="","",VALUE(RIGHT(X535,2))) -> 11 | AI535: =IF(OR(J535<>"Karakter",pub_gid_0_single_true_output_csv[[#This Row],[Nilai2]]=""),"",IF(AF535>89,"Sangat baik",IF(AF535>79,"Baik",IF(AF535>69,"Cukup",IF(AF535>59,"Kurang","Sangat kurang"))))) | AJ535: =IF(AF535="","",CONCATENATE("Wk.",WEEKNUM(F535,2))) -> Wk.4 | AK535: =IF(pub_gid_0_single_true_output_csv[[#This Row],[Nilai2]]="","",VLOOKUP(pub_gid_0_single_true_output_csv[[#This Row],[NAMA]],Table7[],3,FALSE)) -> Average
A536: 535 | B536: 242510011 | C536: 11A | D536: Roison Sondegau | E536: Intan Jaya | F536: 46041 | G536: 19 | H536: Jan | I536: 26 | J536: Teori | K536: Kognitif Formatif | L536: Latihan | M536: Real | N536: Entrepreneur | O536: Product development | P536: Pengolahan Kopi atau Tepung | Q536: Product development | R536: Pengembangan produk inovasi | S536: F11.03.01 | T536: 3 | U536: Pemahaman nutrisi yang terkandung pada makanan terutama pada kopi dan singkong | V536: 03.01 | W536: Nutrisi pada Makanan | X536: K11 | Y536: F | Z536: 65 | AA536: 98 | AB536: Tuntas | AC536: Biologi | AD536: Eka Dewi Sriyani, S.Pd., M.Si., Gr. | AE536: =IF(AF536="","",VLOOKUP(AC536,mapel!$A$2:$B$42,2,FALSE)) -> Biologi | AF536: =IF(AA536=0, "",IF(AA536 = 0.1, 0,AA536)) -> 98 | AG536: =IF(AF536="","",IF(AF536>90,"Sangat baik",IF(AF536>79,"Baik",IF(AF536>=pub_gid_0_single_true_output_csv[[#This Row],[KKM]],"Cukup","Kurang")))) -> Sangat baik | AH536: =IF(AG536="","",VALUE(RIGHT(X536,2))) -> 11 | AI536: =IF(OR(J536<>"Karakter",pub_gid_0_single_true_output_csv[[#This Row],[Nilai2]]=""),"",IF(AF536>89,"Sangat baik",IF(AF536>79,"Baik",IF(AF536>69,"Cukup",IF(AF536>59,"Kurang","Sangat kurang"))))) | AJ536: =IF(AF536="","",CONCATENATE("Wk.",WEEKNUM(F536,2))) -> Wk.4 | AK536: =IF(pub_gid_0_single_true_output_csv[[#This Row],[Nilai2]]="","",VLOOKUP(pub_gid_0_single_true_output_csv[[#This Row],[NAMA]],Table7[],3,FALSE)) -> Extremely low
A537: 536 | B537: 242510004 | C537: 11A | D537: Etty Ebrata Holombau | E537: Inta jaya | F537: 46041 | G537: 19 | H537: Jan | I537: 26 | J537: Teori | K537: Kognitif Formatif | L537: Latihan | M537: Real | N537: Entrepreneur | O537: Product development | P537: Pengolahan Kopi atau Tepung | Q537: Product development | R537: Pengembangan produk inovasi | S537: F11.03.01 | T537: 3 | U537: Pemahaman nutrisi yang terkandung pada makanan terutama pada kopi dan singkong | V537: 03.01 | W537: Nutrisi pada Makanan | X537: K11 | Y537: F | Z537: 65 | AA537: 98 | AB537: Tuntas | AC537: Biologi | AD537: Eka Dewi Sriyani, S.Pd., M.Si., Gr. | AE537: =IF(AF537="","",VLOOKUP(AC537,mapel!$A$2:$B$42,2,FALSE)) -> Biologi | AF537: =IF(AA537=0, "",IF(AA537 = 0.1, 0,AA537)) -> 98 | AG537: =IF(AF537="","",IF(AF537>90,"Sangat baik",IF(AF537>79,"Baik",IF(AF537>=pub_gid_0_single_true_output_csv[[#This Row],[KKM]],"Cukup","Kurang")))) -> Sangat baik | AH537: =IF(AG537="","",VALUE(RIGHT(X537,2))) -> 11 | AI537: =IF(OR(J537<>"Karakter",pub_gid_0_single_true_output_csv[[#This Row],[Nilai2]]=""),"",IF(AF537>89,"Sangat baik",IF(AF537>79,"Baik",IF(AF537>69,"Cukup",IF(AF537>59,"Kurang","Sangat kurang"))))) | AJ537: =IF(AF537="","",CONCATENATE("Wk.",WEEKNUM(F537,2))) -> Wk.4 | AK537: =IF(pub_gid_0_single_true_output_csv[[#This Row],[Nilai2]]="","",VLOOKUP(pub_gid_0_single_true_output_csv[[#This Row],[NAMA]],Table7[],3,FALSE)) -> High average
